/opt/zyp/zyp/datac.py changed, reloading.
Watching for file changes with StatReloader
Performing system checks...

System check identified no issues (0 silenced).
February 06, 2022 - 10:28:53
Django version 3.2.10, using settings 'zyp.settings'
Starting development server at http://0.0.0.0:11112/
Quit the server with CONTROL-C.
/opt/zyp/zyp/datac.py changed, reloading.
Watching for file changes with StatReloader
Performing system checks...

System check identified no issues (0 silenced).
February 06, 2022 - 10:29:08
Django version 3.2.10, using settings 'zyp.settings'
Starting development server at http://0.0.0.0:11112/
Quit the server with CONTROL-C.
/opt/zyp/zyp/datac.py changed, reloading.
Watching for file changes with StatReloader
Performing system checks...

System check identified no issues (0 silenced).
February 06, 2022 - 10:29:49
Django version 3.2.10, using settings 'zyp.settings'
Starting development server at http://0.0.0.0:11112/
Quit the server with CONTROL-C.
/usr/local/python3/lib/python3.6/site-packages/plotnine/ggplot.py:725: PlotnineWarning: Saving 12 x 8 in image.
/usr/local/python3/lib/python3.6/site-packages/plotnine/ggplot.py:726: PlotnineWarning: Filename: /opt/zypimg/467c9942eb6a342fcbf45d5b5bff3179.svg
/usr/local/python3/lib/python3.6/site-packages/matplotlib/textpath.py:74: RuntimeWarning: Glyph 22899 missing from current font.
/usr/local/python3/lib/python3.6/site-packages/matplotlib/textpath.py:74: RuntimeWarning: Glyph 30007 missing from current font.
[06/Feb/2022 10:30:05] "GET /dimg_density_type/?uid=8d288928ff8f90878f83dbdc290f2f77&f_suffix=.dta&argu1=edu_x1&argu2=SEX&width=12&height=8&title= HTTP/1.1" 200 117066
/usr/local/python3/lib/python3.6/site-packages/plotnine/ggplot.py:725: PlotnineWarning: Saving 12 x 8 in image.
/usr/local/python3/lib/python3.6/site-packages/plotnine/ggplot.py:726: PlotnineWarning: Filename: /opt/zypimg/a8a6cd480ac00d3d8c346c2921e8d8e0.svg
/usr/local/python3/lib/python3.6/site-packages/matplotlib/textpath.py:74: RuntimeWarning: Glyph 22899 missing from current font.
/usr/local/python3/lib/python3.6/site-packages/matplotlib/textpath.py:74: RuntimeWarning: Glyph 30007 missing from current font.
[06/Feb/2022 10:30:08] "GET /dimg_density_type/?uid=8d288928ff8f90878f83dbdc290f2f77&f_suffix=.dta&argu1=edu_x1&argu2=SEX&width=12&height=8&title= HTTP/1.1" 200 117066
/opt/zyp/zyp/datac.py changed, reloading.
Watching for file changes with StatReloader
Performing system checks...

Exception in thread django-main-thread:
Traceback (most recent call last):
  File "/usr/local/python3/lib/python3.6/threading.py", line 916, in _bootstrap_inner
    self.run()
  File "/usr/local/python3/lib/python3.6/threading.py", line 864, in run
    self._target(*self._args, **self._kwargs)
  File "/usr/local/python3/lib/python3.6/site-packages/django/utils/autoreload.py", line 64, in wrapper
    fn(*args, **kwargs)
  File "/usr/local/python3/lib/python3.6/site-packages/django/core/management/commands/runserver.py", line 118, in inner_run
    self.check(display_num_errors=True)
  File "/usr/local/python3/lib/python3.6/site-packages/django/core/management/base.py", line 423, in check
    databases=databases,
  File "/usr/local/python3/lib/python3.6/site-packages/django/core/checks/registry.py", line 76, in run_checks
    new_errors = check(app_configs=app_configs, databases=databases)
  File "/usr/local/python3/lib/python3.6/site-packages/django/core/checks/urls.py", line 13, in check_url_config
    return check_resolver(resolver)
  File "/usr/local/python3/lib/python3.6/site-packages/django/core/checks/urls.py", line 23, in check_resolver
    return check_method()
  File "/usr/local/python3/lib/python3.6/site-packages/django/urls/resolvers.py", line 416, in check
    for pattern in self.url_patterns:
  File "/usr/local/python3/lib/python3.6/site-packages/django/utils/functional.py", line 48, in __get__
    res = instance.__dict__[self.name] = self.func(instance)
  File "/usr/local/python3/lib/python3.6/site-packages/django/urls/resolvers.py", line 602, in url_patterns
    patterns = getattr(self.urlconf_module, "urlpatterns", self.urlconf_module)
  File "/usr/local/python3/lib/python3.6/site-packages/django/utils/functional.py", line 48, in __get__
    res = instance.__dict__[self.name] = self.func(instance)
  File "/usr/local/python3/lib/python3.6/site-packages/django/urls/resolvers.py", line 595, in urlconf_module
    return import_module(self.urlconf_name)
  File "/usr/local/python3/lib/python3.6/importlib/__init__.py", line 126, in import_module
    return _bootstrap._gcd_import(name[level:], package, level)
  File "<frozen importlib._bootstrap>", line 994, in _gcd_import
  File "<frozen importlib._bootstrap>", line 971, in _find_and_load
  File "<frozen importlib._bootstrap>", line 955, in _find_and_load_unlocked
  File "<frozen importlib._bootstrap>", line 665, in _load_unlocked
  File "<frozen importlib._bootstrap_external>", line 678, in exec_module
  File "<frozen importlib._bootstrap>", line 219, in _call_with_frames_removed
  File "/opt/zyp/zyp/urls.py", line 20, in <module>
    from . import datac
  File "/opt/zyp/zyp/datac.py", line 83
    df.loc[:,col_name+'_type']=df.
                                 ^
SyntaxError: invalid syntax

/opt/zyp/zyp/datac.py changed, reloading.
Watching for file changes with StatReloader
Performing system checks...

System check identified no issues (0 silenced).
February 06, 2022 - 10:33:42
Django version 3.2.10, using settings 'zyp.settings'
Starting development server at http://0.0.0.0:11112/
Quit the server with CONTROL-C.
/opt/zyp/zyp/datac.py changed, reloading.
Watching for file changes with StatReloader
Performing system checks...

Exception in thread django-main-thread:
Traceback (most recent call last):
  File "/usr/local/python3/lib/python3.6/threading.py", line 916, in _bootstrap_inner
    self.run()
  File "/usr/local/python3/lib/python3.6/threading.py", line 864, in run
    self._target(*self._args, **self._kwargs)
  File "/usr/local/python3/lib/python3.6/site-packages/django/utils/autoreload.py", line 64, in wrapper
    fn(*args, **kwargs)
  File "/usr/local/python3/lib/python3.6/site-packages/django/core/management/commands/runserver.py", line 118, in inner_run
    self.check(display_num_errors=True)
  File "/usr/local/python3/lib/python3.6/site-packages/django/core/management/base.py", line 423, in check
    databases=databases,
  File "/usr/local/python3/lib/python3.6/site-packages/django/core/checks/registry.py", line 76, in run_checks
    new_errors = check(app_configs=app_configs, databases=databases)
  File "/usr/local/python3/lib/python3.6/site-packages/django/core/checks/urls.py", line 13, in check_url_config
    return check_resolver(resolver)
  File "/usr/local/python3/lib/python3.6/site-packages/django/core/checks/urls.py", line 23, in check_resolver
    return check_method()
  File "/usr/local/python3/lib/python3.6/site-packages/django/urls/resolvers.py", line 416, in check
    for pattern in self.url_patterns:
  File "/usr/local/python3/lib/python3.6/site-packages/django/utils/functional.py", line 48, in __get__
    res = instance.__dict__[self.name] = self.func(instance)
  File "/usr/local/python3/lib/python3.6/site-packages/django/urls/resolvers.py", line 602, in url_patterns
    patterns = getattr(self.urlconf_module, "urlpatterns", self.urlconf_module)
  File "/usr/local/python3/lib/python3.6/site-packages/django/utils/functional.py", line 48, in __get__
    res = instance.__dict__[self.name] = self.func(instance)
  File "/usr/local/python3/lib/python3.6/site-packages/django/urls/resolvers.py", line 595, in urlconf_module
    return import_module(self.urlconf_name)
  File "/usr/local/python3/lib/python3.6/importlib/__init__.py", line 126, in import_module
    return _bootstrap._gcd_import(name[level:], package, level)
  File "<frozen importlib._bootstrap>", line 994, in _gcd_import
  File "<frozen importlib._bootstrap>", line 971, in _find_and_load
  File "<frozen importlib._bootstrap>", line 955, in _find_and_load_unlocked
  File "<frozen importlib._bootstrap>", line 665, in _load_unlocked
  File "<frozen importlib._bootstrap_external>", line 678, in exec_module
  File "<frozen importlib._bootstrap>", line 219, in _call_with_frames_removed
  File "/opt/zyp/zyp/urls.py", line 20, in <module>
    from . import datac
  File "/opt/zyp/zyp/datac.py", line 83
    global col_name=col_name
                   ^
SyntaxError: invalid syntax

/opt/zyp/zyp/datac.py changed, reloading.
Watching for file changes with StatReloader
Performing system checks...

Exception in thread django-main-thread:
Traceback (most recent call last):
  File "/usr/local/python3/lib/python3.6/threading.py", line 916, in _bootstrap_inner
    self.run()
  File "/usr/local/python3/lib/python3.6/threading.py", line 864, in run
    self._target(*self._args, **self._kwargs)
  File "/usr/local/python3/lib/python3.6/site-packages/django/utils/autoreload.py", line 64, in wrapper
    fn(*args, **kwargs)
  File "/usr/local/python3/lib/python3.6/site-packages/django/core/management/commands/runserver.py", line 118, in inner_run
    self.check(display_num_errors=True)
  File "/usr/local/python3/lib/python3.6/site-packages/django/core/management/base.py", line 423, in check
    databases=databases,
  File "/usr/local/python3/lib/python3.6/site-packages/django/core/checks/registry.py", line 76, in run_checks
    new_errors = check(app_configs=app_configs, databases=databases)
  File "/usr/local/python3/lib/python3.6/site-packages/django/core/checks/urls.py", line 13, in check_url_config
    return check_resolver(resolver)
  File "/usr/local/python3/lib/python3.6/site-packages/django/core/checks/urls.py", line 23, in check_resolver
    return check_method()
  File "/usr/local/python3/lib/python3.6/site-packages/django/urls/resolvers.py", line 416, in check
    for pattern in self.url_patterns:
  File "/usr/local/python3/lib/python3.6/site-packages/django/utils/functional.py", line 48, in __get__
    res = instance.__dict__[self.name] = self.func(instance)
  File "/usr/local/python3/lib/python3.6/site-packages/django/urls/resolvers.py", line 602, in url_patterns
    patterns = getattr(self.urlconf_module, "urlpatterns", self.urlconf_module)
  File "/usr/local/python3/lib/python3.6/site-packages/django/utils/functional.py", line 48, in __get__
    res = instance.__dict__[self.name] = self.func(instance)
  File "/usr/local/python3/lib/python3.6/site-packages/django/urls/resolvers.py", line 595, in urlconf_module
    return import_module(self.urlconf_name)
  File "/usr/local/python3/lib/python3.6/importlib/__init__.py", line 126, in import_module
    return _bootstrap._gcd_import(name[level:], package, level)
  File "<frozen importlib._bootstrap>", line 994, in _gcd_import
  File "<frozen importlib._bootstrap>", line 971, in _find_and_load
  File "<frozen importlib._bootstrap>", line 955, in _find_and_load_unlocked
  File "<frozen importlib._bootstrap>", line 665, in _load_unlocked
  File "<frozen importlib._bootstrap_external>", line 678, in exec_module
  File "<frozen importlib._bootstrap>", line 219, in _call_with_frames_removed
  File "/opt/zyp/zyp/urls.py", line 20, in <module>
    from . import datac
  File "/opt/zyp/zyp/datac.py", line 83
    global c_name=col_name
                 ^
SyntaxError: invalid syntax

/opt/zyp/zyp/datac.py changed, reloading.
Watching for file changes with StatReloader
Performing system checks...

System check identified no issues (0 silenced).
February 06, 2022 - 10:35:03
Django version 3.2.10, using settings 'zyp.settings'
Starting development server at http://0.0.0.0:11112/
Quit the server with CONTROL-C.
/opt/zyp/zyp/datac.py changed, reloading.
Watching for file changes with StatReloader
Performing system checks...

System check identified no issues (0 silenced).
February 06, 2022 - 10:36:04
Django version 3.2.10, using settings 'zyp.settings'
Starting development server at http://0.0.0.0:11112/
Quit the server with CONTROL-C.
/opt/zyp/zyp/datac.py changed, reloading.
Watching for file changes with StatReloader
Performing system checks...

System check identified no issues (0 silenced).
February 06, 2022 - 10:37:58
Django version 3.2.10, using settings 'zyp.settings'
Starting development server at http://0.0.0.0:11112/
Quit the server with CONTROL-C.
/opt/zyp/zyp/datac.py changed, reloading.
Watching for file changes with StatReloader
Performing system checks...

Exception in thread django-main-thread:
Traceback (most recent call last):
  File "/usr/local/python3/lib/python3.6/threading.py", line 916, in _bootstrap_inner
    self.run()
  File "/usr/local/python3/lib/python3.6/threading.py", line 864, in run
    self._target(*self._args, **self._kwargs)
  File "/usr/local/python3/lib/python3.6/site-packages/django/utils/autoreload.py", line 64, in wrapper
    fn(*args, **kwargs)
  File "/usr/local/python3/lib/python3.6/site-packages/django/core/management/commands/runserver.py", line 118, in inner_run
    self.check(display_num_errors=True)
  File "/usr/local/python3/lib/python3.6/site-packages/django/core/management/base.py", line 423, in check
    databases=databases,
  File "/usr/local/python3/lib/python3.6/site-packages/django/core/checks/registry.py", line 76, in run_checks
    new_errors = check(app_configs=app_configs, databases=databases)
  File "/usr/local/python3/lib/python3.6/site-packages/django/core/checks/urls.py", line 13, in check_url_config
    return check_resolver(resolver)
  File "/usr/local/python3/lib/python3.6/site-packages/django/core/checks/urls.py", line 23, in check_resolver
    return check_method()
  File "/usr/local/python3/lib/python3.6/site-packages/django/urls/resolvers.py", line 416, in check
    for pattern in self.url_patterns:
  File "/usr/local/python3/lib/python3.6/site-packages/django/utils/functional.py", line 48, in __get__
    res = instance.__dict__[self.name] = self.func(instance)
  File "/usr/local/python3/lib/python3.6/site-packages/django/urls/resolvers.py", line 602, in url_patterns
    patterns = getattr(self.urlconf_module, "urlpatterns", self.urlconf_module)
  File "/usr/local/python3/lib/python3.6/site-packages/django/utils/functional.py", line 48, in __get__
    res = instance.__dict__[self.name] = self.func(instance)
  File "/usr/local/python3/lib/python3.6/site-packages/django/urls/resolvers.py", line 595, in urlconf_module
    return import_module(self.urlconf_name)
  File "/usr/local/python3/lib/python3.6/importlib/__init__.py", line 126, in import_module
    return _bootstrap._gcd_import(name[level:], package, level)
  File "<frozen importlib._bootstrap>", line 994, in _gcd_import
  File "<frozen importlib._bootstrap>", line 971, in _find_and_load
  File "<frozen importlib._bootstrap>", line 955, in _find_and_load_unlocked
  File "<frozen importlib._bootstrap>", line 665, in _load_unlocked
  File "<frozen importlib._bootstrap_external>", line 678, in exec_module
  File "<frozen importlib._bootstrap>", line 219, in _call_with_frames_removed
  File "/opt/zyp/zyp/urls.py", line 20, in <module>
    from . import datac
  File "/opt/zyp/zyp/datac.py", line 84
    return df.loc[:,col_name+'_type']=df.apply(heter_compare_apply,axis=1,args=(col_name,s))
                                     ^
SyntaxError: invalid syntax

/opt/zyp/zyp/datac.py changed, reloading.
Watching for file changes with StatReloader
Performing system checks...

System check identified no issues (0 silenced).
February 06, 2022 - 10:38:16
Django version 3.2.10, using settings 'zyp.settings'
Starting development server at http://0.0.0.0:11112/
Quit the server with CONTROL-C.
/opt/zyp/zyp/datac.py changed, reloading.
Watching for file changes with StatReloader
Performing system checks...

System check identified no issues (0 silenced).
February 06, 2022 - 10:49:17
Django version 3.2.10, using settings 'zyp.settings'
Starting development server at http://0.0.0.0:11112/
Quit the server with CONTROL-C.
/opt/zyp/zyp/imgc.py changed, reloading.
Watching for file changes with StatReloader
Performing system checks...

Exception in thread django-main-thread:
Traceback (most recent call last):
  File "/usr/local/python3/lib/python3.6/threading.py", line 916, in _bootstrap_inner
    self.run()
  File "/usr/local/python3/lib/python3.6/threading.py", line 864, in run
    self._target(*self._args, **self._kwargs)
  File "/usr/local/python3/lib/python3.6/site-packages/django/utils/autoreload.py", line 64, in wrapper
    fn(*args, **kwargs)
  File "/usr/local/python3/lib/python3.6/site-packages/django/core/management/commands/runserver.py", line 118, in inner_run
    self.check(display_num_errors=True)
  File "/usr/local/python3/lib/python3.6/site-packages/django/core/management/base.py", line 423, in check
    databases=databases,
  File "/usr/local/python3/lib/python3.6/site-packages/django/core/checks/registry.py", line 76, in run_checks
    new_errors = check(app_configs=app_configs, databases=databases)
  File "/usr/local/python3/lib/python3.6/site-packages/django/core/checks/urls.py", line 13, in check_url_config
    return check_resolver(resolver)
  File "/usr/local/python3/lib/python3.6/site-packages/django/core/checks/urls.py", line 23, in check_resolver
    return check_method()
  File "/usr/local/python3/lib/python3.6/site-packages/django/urls/resolvers.py", line 416, in check
    for pattern in self.url_patterns:
  File "/usr/local/python3/lib/python3.6/site-packages/django/utils/functional.py", line 48, in __get__
    res = instance.__dict__[self.name] = self.func(instance)
  File "/usr/local/python3/lib/python3.6/site-packages/django/urls/resolvers.py", line 602, in url_patterns
    patterns = getattr(self.urlconf_module, "urlpatterns", self.urlconf_module)
  File "/usr/local/python3/lib/python3.6/site-packages/django/utils/functional.py", line 48, in __get__
    res = instance.__dict__[self.name] = self.func(instance)
  File "/usr/local/python3/lib/python3.6/site-packages/django/urls/resolvers.py", line 595, in urlconf_module
    return import_module(self.urlconf_name)
  File "/usr/local/python3/lib/python3.6/importlib/__init__.py", line 126, in import_module
    return _bootstrap._gcd_import(name[level:], package, level)
  File "<frozen importlib._bootstrap>", line 994, in _gcd_import
  File "<frozen importlib._bootstrap>", line 971, in _find_and_load
  File "<frozen importlib._bootstrap>", line 955, in _find_and_load_unlocked
  File "<frozen importlib._bootstrap>", line 665, in _load_unlocked
  File "<frozen importlib._bootstrap_external>", line 678, in exec_module
  File "<frozen importlib._bootstrap>", line 219, in _call_with_frames_removed
  File "/opt/zyp/zyp/urls.py", line 21, in <module>
    from . import imgc
  File "/opt/zyp/zyp/imgc.py", line 15, in <module>
    from datac import heter_compare_apply,heter_compare_df
ModuleNotFoundError: No module named 'datac'

/opt/zyp/zyp/imgc.py changed, reloading.
Watching for file changes with StatReloader
Performing system checks...

System check identified no issues (0 silenced).
February 06, 2022 - 10:50:54
Django version 3.2.10, using settings 'zyp.settings'
Starting development server at http://0.0.0.0:11112/
Quit the server with CONTROL-C.
/usr/local/python3/lib/python3.6/site-packages/plotnine/ggplot.py:725: PlotnineWarning: Saving 12 x 8 in image.
/usr/local/python3/lib/python3.6/site-packages/plotnine/ggplot.py:726: PlotnineWarning: Filename: /opt/zypimg/f1435f5ecb616f8d1a3bd713965dabdb.svg
/usr/local/python3/lib/python3.6/site-packages/matplotlib/textpath.py:74: RuntimeWarning: Glyph 22899 missing from current font.
/usr/local/python3/lib/python3.6/site-packages/matplotlib/textpath.py:74: RuntimeWarning: Glyph 30007 missing from current font.
[06/Feb/2022 10:50:54] "GET /dimg_density_type/?uid=8d288928ff8f90878f83dbdc290f2f77&f_suffix=.dta&argu1=edu_x1&argu2=SEX&width=12&height=8&title= HTTP/1.1" 200 117066
/opt/zyp/zyp/imgc.py changed, reloading.
Watching for file changes with StatReloader
Performing system checks...

System check identified no issues (0 silenced).
February 06, 2022 - 10:51:57
Django version 3.2.10, using settings 'zyp.settings'
Starting development server at http://0.0.0.0:11112/
Quit the server with CONTROL-C.
/opt/zyp/zyp/imgc.py changed, reloading.
Watching for file changes with StatReloader
Performing system checks...

System check identified no issues (0 silenced).
February 06, 2022 - 10:52:01
Django version 3.2.10, using settings 'zyp.settings'
Starting development server at http://0.0.0.0:11112/
Quit the server with CONTROL-C.
/opt/zyp/zyp/imgc.py changed, reloading.
Watching for file changes with StatReloader
Performing system checks...

System check identified no issues (0 silenced).
February 06, 2022 - 10:52:29
Django version 3.2.10, using settings 'zyp.settings'
Starting development server at http://0.0.0.0:11112/
Quit the server with CONTROL-C.
/opt/zyp/zyp/imgc.py changed, reloading.
Watching for file changes with StatReloader
Performing system checks...

System check identified no issues (0 silenced).
February 06, 2022 - 10:52:32
Django version 3.2.10, using settings 'zyp.settings'
Starting development server at http://0.0.0.0:11112/
Quit the server with CONTROL-C.
/opt/zyp/zyp/imgc.py changed, reloading.
Watching for file changes with StatReloader
Performing system checks...

System check identified no issues (0 silenced).
February 06, 2022 - 10:52:40
Django version 3.2.10, using settings 'zyp.settings'
Starting development server at http://0.0.0.0:11112/
Quit the server with CONTROL-C.
[06/Feb/2022 10:52:49] "GET /dimg_hetero_density/?uid=8d288928ff8f90878f83dbdc290f2f77&f_suffix=.dta&argu1=AGE&segment=40&width=&height=&title= HTTP/1.1" 200 66
/usr/local/python3/lib/python3.6/site-packages/plotnine/ggplot.py:725: PlotnineWarning: Saving 12 x 8 in image.
/usr/local/python3/lib/python3.6/site-packages/plotnine/ggplot.py:726: PlotnineWarning: Filename: /opt/zypimg/1aca7a3b087c3ab709be1a93cfc189cd.svg
Internal Server Error: /dimg_hetero_density/
Traceback (most recent call last):
  File "/usr/local/python3/lib/python3.6/site-packages/django/core/handlers/exception.py", line 47, in inner
    response = get_response(request)
  File "/usr/local/python3/lib/python3.6/site-packages/django/core/handlers/base.py", line 181, in _get_response
    response = wrapped_callback(request, *callback_args, **callback_kwargs)
  File "/opt/zyp/zyp/imgc.py", line 88, in hetero_density
    return sav_and_ret_svg(img_density,width,height)
  File "/opt/zyp/zyp/imgc.py", line 25, in sav_and_ret_svg
    img.save(os.path.join(image_path,f_name),format="svg",width=width,height=height)
  File "/usr/local/python3/lib/python3.6/site-packages/plotnine/ggplot.py", line 731, in save
    fig, p = self.draw(return_ggplot=True)
  File "/usr/local/python3/lib/python3.6/site-packages/plotnine/ggplot.py", line 209, in draw
    self._build()
  File "/usr/local/python3/lib/python3.6/site-packages/plotnine/ggplot.py", line 304, in _build
    layers.compute_statistic(layout)
  File "/usr/local/python3/lib/python3.6/site-packages/plotnine/layer.py", line 73, in compute_statistic
    l.compute_statistic(layout)
  File "/usr/local/python3/lib/python3.6/site-packages/plotnine/layer.py", line 324, in compute_statistic
    data = self.stat.compute_layer(data, params, layout)
  File "/usr/local/python3/lib/python3.6/site-packages/plotnine/stats/stat.py", line 255, in compute_layer
    cls.__name__)
  File "/usr/local/python3/lib/python3.6/site-packages/plotnine/utils.py", line 385, in check_required_aesthetics
    msg.format(name, ', '.join(missing_aes)))
plotnine.exceptions.PlotnineError: 'stat_density requires the following missing aesthetics: x'
[06/Feb/2022 10:53:01] "GET /dimg_hetero_density/?uid=8d288928ff8f90878f83dbdc290f2f77&f_suffix=.dta&argu1=AGE&segment=40&title= HTTP/1.1" 500 100651
/opt/zyp/zyp/imgc.py changed, reloading.
Watching for file changes with StatReloader
Performing system checks...

System check identified no issues (0 silenced).
February 06, 2022 - 10:54:15
Django version 3.2.10, using settings 'zyp.settings'
Starting development server at http://0.0.0.0:11112/
Quit the server with CONTROL-C.
/usr/local/python3/lib/python3.6/site-packages/plotnine/ggplot.py:725: PlotnineWarning: Saving 12 x 8 in image.
/usr/local/python3/lib/python3.6/site-packages/plotnine/ggplot.py:726: PlotnineWarning: Filename: /opt/zypimg/2df7393480615873f2c015d8ca14d3b1.svg
[06/Feb/2022 10:54:17] "GET /dimg_hetero_density/?uid=8d288928ff8f90878f83dbdc290f2f77&f_suffix=.dta&argu1=AGE&segment=40&title= HTTP/1.1" 200 115990
/usr/local/python3/lib/python3.6/site-packages/plotnine/ggplot.py:725: PlotnineWarning: Saving 12 x 8 in image.
/usr/local/python3/lib/python3.6/site-packages/plotnine/ggplot.py:726: PlotnineWarning: Filename: /opt/zypimg/88459ec5472550ae9610b29c349fcc4b.svg
[06/Feb/2022 10:54:26] "GET /dimg_hetero_density/?uid=8d288928ff8f90878f83dbdc290f2f77&f_suffix=.dta&argu1=AGE&segment=40&title= HTTP/1.1" 200 115990
/usr/local/python3/lib/python3.6/site-packages/plotnine/ggplot.py:725: PlotnineWarning: Saving 12 x 8 in image.
/usr/local/python3/lib/python3.6/site-packages/plotnine/ggplot.py:726: PlotnineWarning: Filename: /opt/zypimg/e7e31ec4716d3667d725f411eb00ad1b.svg
[06/Feb/2022 10:54:40] "GET /dimg_hetero_density/?uid=8d288928ff8f90878f83dbdc290f2f77&f_suffix=.dta&argu1=AGE&segment=45&title= HTTP/1.1" 200 116843
/usr/local/python3/lib/python3.6/site-packages/plotnine/ggplot.py:725: PlotnineWarning: Saving 12 x 8 in image.
/usr/local/python3/lib/python3.6/site-packages/plotnine/ggplot.py:726: PlotnineWarning: Filename: /opt/zypimg/e342375e3b10d6567107a2cc60744780.svg
[06/Feb/2022 10:54:48] "GET /dimg_hetero_density/?uid=8d288928ff8f90878f83dbdc290f2f77&f_suffix=.dta&argu1=AGE&segment=70&title= HTTP/1.1" 200 115538
/usr/local/python3/lib/python3.6/site-packages/plotnine/ggplot.py:725: PlotnineWarning: Saving 12 x 8 in image.
/usr/local/python3/lib/python3.6/site-packages/plotnine/ggplot.py:726: PlotnineWarning: Filename: /opt/zypimg/7b4d28ca31a2ff9522f5daa634616378.svg
[06/Feb/2022 10:55:27] "GET /dimg_hetero_density/?uid=8d288928ff8f90878f83dbdc290f2f77&f_suffix=.dta&argu1=AGE&segment=70&title= HTTP/1.1" 200 115538
/usr/local/python3/lib/python3.6/site-packages/plotnine/ggplot.py:725: PlotnineWarning: Saving 12 x 8 in image.
/usr/local/python3/lib/python3.6/site-packages/plotnine/ggplot.py:726: PlotnineWarning: Filename: /opt/zypimg/361b34eb08bbcbe27b05ca062a28713d.svg
[06/Feb/2022 10:55:37] "GET /dimg_hetero_density/?uid=8d288928ff8f90878f83dbdc290f2f77&f_suffix=.dta&argu1=AGE&segment=70&title= HTTP/1.1" 200 115538
/usr/local/python3/lib/python3.6/site-packages/plotnine/ggplot.py:725: PlotnineWarning: Saving 12 x 8 in image.
/usr/local/python3/lib/python3.6/site-packages/plotnine/ggplot.py:726: PlotnineWarning: Filename: /opt/zypimg/6cf44bd572835df043816fea9658cc0f.svg
[06/Feb/2022 10:56:23] "GET /dimg_hetero_density/?uid=8d288928ff8f90878f83dbdc290f2f77&f_suffix=.dta&argu1=AGE&segment=70&title= HTTP/1.1" 200 115538
/usr/local/python3/lib/python3.6/site-packages/plotnine/ggplot.py:725: PlotnineWarning: Saving 12 x 8 in image.
/usr/local/python3/lib/python3.6/site-packages/plotnine/ggplot.py:726: PlotnineWarning: Filename: /opt/zypimg/00dcb9259b7d89abe63bd2ba49035abf.svg
[06/Feb/2022 10:56:49] "GET /dimg_hetero_density/?uid=8d288928ff8f90878f83dbdc290f2f77&f_suffix=.dta&argu1=AGE&segment=70&title=Heterogeneity%20analysis%20test HTTP/1.1" 200 131967
/usr/local/python3/lib/python3.6/site-packages/plotnine/ggplot.py:725: PlotnineWarning: Saving 12 x 8 in image.
/usr/local/python3/lib/python3.6/site-packages/plotnine/ggplot.py:726: PlotnineWarning: Filename: /opt/zypimg/71025d710140fd9dd908a13209726707.svg
[06/Feb/2022 10:57:12] "GET /dimg_hetero_density/?uid=8d288928ff8f90878f83dbdc290f2f77&f_suffix=.dta&argu1=edu_x1&segment=70&title=Heterogeneity%20analysis%20test HTTP/1.1" 200 81790
/usr/local/python3/lib/python3.6/site-packages/plotnine/ggplot.py:725: PlotnineWarning: Saving 12 x 8 in image.
/usr/local/python3/lib/python3.6/site-packages/plotnine/ggplot.py:726: PlotnineWarning: Filename: /opt/zypimg/6240739e3bf1769bf0d56ecc6e206749.svg
[06/Feb/2022 10:57:24] "GET /dimg_hetero_density/?uid=8d288928ff8f90878f83dbdc290f2f77&f_suffix=.dta&argu1=edu_x1&segment=5&title=Heterogeneity%20analysis%20test HTTP/1.1" 200 130875
/usr/local/python3/lib/python3.6/site-packages/plotnine/ggplot.py:725: PlotnineWarning: Saving 12 x 8 in image.
/usr/local/python3/lib/python3.6/site-packages/plotnine/ggplot.py:726: PlotnineWarning: Filename: /opt/zypimg/1808c90d8d075f58da540fb57929439b.svg
[06/Feb/2022 10:57:49] "GET /dimg_hetero_density/?uid=8d288928ff8f90878f83dbdc290f2f77&f_suffix=.dta&argu1=edu_x1&segment=5&title= HTTP/1.1" 200 113804
/usr/local/python3/lib/python3.6/site-packages/plotnine/ggplot.py:725: PlotnineWarning: Saving 12 x 8 in image.
/usr/local/python3/lib/python3.6/site-packages/plotnine/ggplot.py:726: PlotnineWarning: Filename: /opt/zypimg/e90a83baf080f2e5b4cb53e2aa5a8a10.svg
[06/Feb/2022 10:58:01] "GET /dimg_hetero_density/?uid=8d288928ff8f90878f83dbdc290f2f77&f_suffix=.dta&argu1=edu_x1&segment=5&title= HTTP/1.1" 200 113804
/usr/local/python3/lib/python3.6/site-packages/plotnine/ggplot.py:725: PlotnineWarning: Saving 12 x 8 in image.
/usr/local/python3/lib/python3.6/site-packages/plotnine/ggplot.py:726: PlotnineWarning: Filename: /opt/zypimg/8f4d785589db6a22c7c68c7097da362e.svg
[06/Feb/2022 10:58:14] "GET /dimg_hetero_density/?uid=8d288928ff8f90878f83dbdc290f2f77&f_suffix=.dta&argu1=AGE&segment=70&title=Heterogeneity%20analysis%20test HTTP/1.1" 200 131967
/usr/local/python3/lib/python3.6/site-packages/plotnine/ggplot.py:725: PlotnineWarning: Saving 12 x 8 in image.
/usr/local/python3/lib/python3.6/site-packages/plotnine/ggplot.py:726: PlotnineWarning: Filename: /opt/zypimg/52e773d5ac8ecfab9902722db92d84ae.svg
/usr/local/python3/lib/python3.6/site-packages/matplotlib/textpath.py:74: RuntimeWarning: Glyph 22899 missing from current font.
/usr/local/python3/lib/python3.6/site-packages/matplotlib/textpath.py:74: RuntimeWarning: Glyph 30007 missing from current font.
[06/Feb/2022 10:59:10] "GET /dimg_density_type/?uid=8d288928ff8f90878f83dbdc290f2f77&f_suffix=.dta&argu1=edu_x1&argu2=SEX&width=12&height=8&title= HTTP/1.1" 200 117066
